Workbook

Sheet Index
B2: Tasks by Tool
C3: 1. Excel | F3: Sheet Names | G3: Notes
D4: ● Task 1: Import the dataset into Excel and clean the data. | F4: 1. co2_data 2. Country_Parameter | G4: Raw data that includes only specific column that directly contributes for CO2 emission
E5: ○ Handle missing values, duplicates, and formatting issues. | G5: Created to bifurcate the data in country column according to country, Continent, Continent(GCP), OECD & Income Group
D6: ● Task 2: Perform basic descriptive analysis: | F6: 1. Pivot 2. Linear Param 0 & 1 3. Linear Param 0 & 2 4. Linear Param 0 & 3 5. Linear Param 0 & 4 5. Linear Param 0 & 5 7. All totals | G6: This Tables represents that the by grouping each parameter with Parameter 0 gives the total emission by world
E7: ○ Calculate average, maximum, and minimum emissions by year.
E8: ○ Create pivot tables to analyze emissions by country and sector.
D9: ● Task 3: Visualize trends using: | F9: 1. Calculations 2. Graphical representation | G9: 1. Calculations are done based on emmision of world and also table shows bifurcation on Total CO2 emissions in terms of Cement, Coal, Flarings, Gas, Oil and other industries 2. Graphical representation shows trend line of total CO2 emission till 2023 and also emission forcast till 2072. 3. Next Graph shows the CO2 Emmision forecasting for each Sector in a specific year. 4. Further Graphs shows the Scatered graph(this represent the linear trend line with equation, to predict the forecast) and Line Graph shows the trend in future
E10: ○ Line charts for global emissions over time.
E11: ○ Bar charts for sector-wise emissions in a specific year.

Sheet Country_Parameter
A1: country | B1: define | C1: param_type
A2: North America | B2: Continent | C2: Parameter 4
A3: Canada | B3: country | C3: Parameter 1
A4: United States | B4: country | C4: Parameter 1
A5: Mexico | B5: country | C5: Parameter 1
A6: Saint Pierre and Miquelon | B6: country | C6: Parameter 1
A7: Greenland | B7: country | C7: Parameter 1
A8: South America | B8: Continent | C8: Parameter 4
A9: Brazil | B9: country | C9: Parameter 1
A10: Argentina | B10: country | C10: Parameter 1
A11: Chile | B11: country | C11: Parameter 1
A12: Colombia | B12: country | C12: Parameter 1
... A275: World | B275: Others | C275: Others

Sheet co2_data
A1: country | B1: year | C1: param_type | D1: population | E1: gdp | F1: cement_co2 | G1: co2 | H1: coal_co2 | I1: flaring_co2 | J1: gas_co2 | K1: oil_co2 | L1: other_industry_co2
A2: Afghanistan | B2: 1949 | C2: =VLOOKUP(co2_data[[#This Row],[country]],Country_Parameter!A:C,3,0) -> Parameter 1 | D2: 7356890 | E2: 0 | F2: 0 | G2: 0 | H2: 0 | I2: 0 | J2: 0 | K2: 0 | L2: 0
A3: Afghanistan | B3: 1950 | C3: =VLOOKUP(co2_data[[#This Row],[country]],Country_Parameter!A:C,3,0) -> Parameter 1 | D3: 7776182 | E3: 9421400064 | F3: 0 | G3: 0 | H3: 0 | I3: 0 | J3: 0 | K3: 0 | L3: 0
A4: Afghanistan | B4: 1951 | C4: =VLOOKUP(co2_data[[#This Row],[country]],Country_Parameter!A:C,3,0) -> Parameter 1 | D4: 7879343 | E4: 9692279808 | F4: 0 | G4: 0 | H4: 0 | I4: 0 | J4: 0 | K4: 0 | L4: 0
A5: Afghanistan | B5: 1952 | C5: =VLOOKUP(co2_data[[#This Row],[country]],Country_Parameter!A:C,3,0) -> Parameter 1 | D5: 7987783 | E5: 10017325056 | F5: 0 | G5: 0 | H5: 0 | I5: 0 | J5: 0 | K5: 0 | L5: 0
A6: Afghanistan | B6: 1953 | C6: =VLOOKUP(co2_data[[#This Row],[country]],Country_Parameter!A:C,3,0) -> Parameter 1 | D6: 8096703 | E6: 10630519808 | F6: 0 | G6: 0 | H6: 0 | I6: 0 | J6: 0 | K6: 0 | L6: 0
A7: Afghanistan | B7: 1954 | C7: =VLOOKUP(co2_data[[#This Row],[country]],Country_Parameter!A:C,3,0) -> Parameter 1 | D7: 8207953 | E7: 10866360320 | F7: 0 | G7: 0 | H7: 0 | I7: 0 | J7: 0 | K7: 0 | L7: 0
A8: Afghanistan | B8: 1955 | C8: =VLOOKUP(co2_data[[#This Row],[country]],Country_Parameter!A:C,3,0) -> Parameter 1 | D8: 8326981 | E8: 11078185984 | F8: 0 | G8: 0 | H8: 0 | I8: 0 | J8: 0 | K8: 0 | L8: 0
A9: Afghanistan | B9: 1956 | C9: =VLOOKUP(co2_data[[#This Row],[country]],Country_Parameter!A:C,3,0) -> Parameter 1 | D9: 8454302 | E9: 11581236224 | F9: 0 | G9: 0 | H9: 0 | I9: 0 | J9: 0 | K9: 0 | L9: 0
A10: Afghanistan | B10: 1957 | C10: =VLOOKUP(co2_data[[#This Row],[country]],Country_Parameter!A:C,3,0) -> Parameter 1 | D10: 8588340 | E10: 11578973184 | F10: 0 | G10: 0 | H10: 0 | I10: 0 | J10: 0 | K10: 0 | L10: 0
A11: Afghanistan | B11: 1958 | C11: =VLOOKUP(co2_data[[#This Row],[country]],Country_Parameter!A:C,3,0) -> Parameter 1 | D11: 8723412 | E11: 12238841856 | F11: 0 | G11: 0 | H11: 0 | I11: 0 | J11: 0 | K11: 0 | L11: 0
A12: Afghanistan | B12: 1959 | C12: =VLOOKUP(co2_data[[#This Row],[country]],Country_Parameter!A:C,3,0) -> Parameter 1 | D12: 8869271 | E12: 12579874816 | F12: 0 | G12: 0 | H12: 0 | I12: 0 | J12: 0 | K12: 0 | L12: 0
A13: Afghanistan | B13: 1960 | C13: =VLOOKUP(co2_data[[#This Row],[country]],Country_Parameter!A:C,3,0) -> Parameter 1 | D13: 9035048 | E13: 13033253888 | F13: 0 | G13: 0 | H13: 0 | I13: 0 | J13: 0 | K13: 0 | L13: 0
... A19017: Zimbabwe | B19017: 2023 | C19017: =VLOOKUP(co2_data[[#This Row],[country]],Country_Parameter!A:C,3,0) -> Parameter 1 | D19017: 16340829 | E19017: 0 | F19017: 1 | G19017: 11 | H19017: 7 | I19017: 0 | J19017: 0 | K19017: 3 | L19017: 0

Sheet Linear Param 0 & 1
B3: Country wise CO2 emission data including international Aviation and Shipping
B5: Year | C5: Parameter 1 & 0 | HM5: Grand Total | HN5: Average | HO5: Maximum | HP5: Minimum
C6: United States | D6: China | E6: Russia | F6: Germany | G6: Japan | H6: India | I6: United Kingdom | J6: Canada | K6: Ukraine | L6: International shipping | M6: France | N6: Italy | O6: Poland | P6: South Africa | Q6: Iran | R6: Mexico | S6: South Korea | T6: Australia | U6: Saudi Arabia | V6: Brazil | W6: International aviation | X6: Indonesia | Y6: Spain | Z6: Kazakhstan | AA6: Turkey | AB6: Netherlands | AC6: Taiwan | AD6: Czechia | AE6: Argentina | AF6: Belgium | AG6: Romania | AH6: Thailand | AI6: Venezuela | AJ6: Egypt | AK6: Malaysia | AL6: Uzbekistan | AM6: Pakistan | AN6: United Arab Emirates | AO6: North Korea | AP6: Algeria | AQ6: Vietnam | AR6: Belarus | AS6: Iraq | AT6: Nigeria | AU6: Hungary | AV6: Sweden | AW6: Greece | AX6: Austria | AY6: Bulgaria | AZ6: Philippines | BA6: Kuwait | BB6: Colombia | BC6: Denmark | BD6: Finland | BE6: Slovakia | BF6: Chile | BG6: Serbia | BH6: Switzerland | BI6: Israel | BJ6: Portugal | BK6: Turkmenistan | BL6: Azerbaijan | BM6: Libya | BN6: Qatar | BO6: Norway | BP6: Singapore | BQ6: Ireland | BR6: Syria | BS6: Morocco | BT6: Bangladesh | BU6: Peru | BV6: New Zealand | BW6: Hong Kong | BX6: Cuba | BY6: Oman | BZ6: Estonia | CA6: Trinidad and Tobago | CB6: Lithuania | CC6: Ecuador | CD6: Moldova | CE6: Croatia | CF6: Bahrain | CG6: Tunisia | CH6: Bosnia and Herzegovina | CI6: Latvia | CJ6: Slovenia | CK6: Dominican Republic | CL6: Mongolia | CM6: Kyrgyzstan | CN6: Lebanon | CO6: Luxembourg | CP6: Jordan | CQ6: Zimbabwe | CR6: Angola | CS6: Yemen | CT6: Georgia | CU6: Myanmar | CV6: Bolivia | CW6: Sri Lanka | CX6: Kenya | CY6: Curacao | CZ6: North Macedonia | DA6: Sudan | DB6: Guatemala | DC6: Jamaica | DD6: Tajikistan | DE6: Ghana | DF6: Uruguay | DG6: Brunei | DH6: Cote d'Ivoire | DI6: Armenia | DJ6: Panama | DK6: Tanzania | DL6: Cyprus | DM6: Ethiopia | DN6: Gabon | DO6: Cameroon | DP6: Albania | DQ6: Honduras | DR6: Senegal | DS6: Costa Rica | DT6: Zambia | DU6: El Salvador | DV6: Afghanistan | DW6: Democratic Republic of Congo | DX6: Cambodia | DY6: Laos | DZ6: Nepal | EA6: Papua New Guinea | EB6: Paraguay | EC6: Mozambique | ED6: Nicaragua | EE6: Congo | EF6: Bahamas | EG6: Botswana | EH6: New Caledonia | EI6: Iceland | EJ6: Equatorial Guinea | EK6: Kosovo | EL6: Mauritius | EM6: Suriname | EN6: Uganda | EO6: Benin | EP6: Guyana | EQ6: Madagascar | ER6: Malta | ES6: Montenegro | ET6: Guinea | EU6: Mauritania | EV6: Mali | EW6: Namibia | EX6: Burkina Faso | EY6: Haiti | EZ6: Lesotho | FA6: Aruba | FB6: Togo | FC6: Palestine | FD6: Barbados | FE6: Sint Maarten (Dutch part) | FF6: Niger | FG6: Macao | FH6: Malawi | FI6: Liberia | FJ6: Fiji | FK6: Chad | FL6: Eswatini | FM6: South Sudan | FN6: Sierra Leone | FO6: Greenland | FP6: Somalia | FQ6: Rwanda | FR6: French Polynesia | FS6: Faroe Islands | FT6: Maldives | FU6: Bermuda | FV6: Bhutan | FW6: Antigua and Barbuda | FX6: Belize | FY6: Djibouti | FZ6: Eritrea | GA6: Gambia | GB6: Andorra | GC6: Cape Verde | GD6: Saint Lucia | GE6: Burundi | GF6: Seychelles | GG6: Central African Republic | GH6: East Timor | GI6: Solomon Islands | GJ6: Palau | GK6: Guinea-Bissau | GL6: Liechtenstein | GM6: Grenada | GN6: Saint Kitts and Nevis | GO6: Saint Vincent and the Grenadines | GP6: Bonaire Sint Eustatius and Saba | GQ6: Samoa | GR6: Turks and Caicos Islands | GS6: Comoros | GT6: British Virgin Islands | GU6: Vanuatu | GV6: Dominica | GW6: Nauru | GX6: Tonga | GY6: Micronesia (country) | GZ6: Sao Tome and Principe | HA6: Saint Pierre and Miquelon | HB6: Marshall Islands | HC6: Anguilla | HD6: Cook Islands | HE6: Kiribati | HF6: Montserrat | HG6: Christmas Island | HH6: Wallis and Futuna | HI6: Saint Helena | HJ6: Tuvalu | HK6: Niue | HL6: Antarctica
B7: 1949 | C7: 2164.862 | D7: 62.081 | E7: 372.365 | F7: 432.148 | G7: 98.42 | H7: 56.188 | I7: 507.552 | J7: 145.022 | K7: 118.135 | L7: 0 | M7: 229.051 | N7: 39.771 | O7: 105.426 | P7: 60.586 | Q7: 8.13 | R7: 28.959 | S7: 2.176 | T7: 48.064 | U7: 18.386 | V7: 7.367 | W7: 0 | X7: 21.903 | Y7: 35.755 | Z7: 40.496 | AA7: 7.968 | AB7: 50.499 | AC7: 4.473 | AD7: 56.189 | AE7: 15.365 | AF7: 80.772 | AG7: 23.114 | AH7: 0.062 | AI7: 28.775 | AJ7: 7.46 | AK7: 1.22 | AL7: 15.428 | AM7: 1.025 | AN7: 0 | AO7: 1.781 | AP7: 0.908 | AQ7: 1.077 | AR7: 16.922 | AS7: 1.128 | AT7: 1.484 | AU7: 20.41 | AV7: 26.832 | AW7: 1.64 | AX7: 26.574 | AY7: 7.453 | AZ7: 0.318 | BA7: 1.063 | BB7: 5.867 | BC7: 16.88 | BD7: 4.933 | BE7: 17.99 | BF7: 5.184 | BG7: 8.256 | BH7: 8.53 | BI7: 0.12 | BJ7: 5.52 | BK7: 5.089 | BL7: 8.042 | BM7: 0 | BN7: 0.26 | BO7: 10.407 | BP7: 0 | BQ7: 8.345 | BR7: 0.029 | BS7: 1.087 | BT7: 0.19 | BU7: 6.593 | BV7: 5.609 | BW7: 0.029 | BX7: 0.339 | BY7: 0 | BZ7: 6.144 | CA7: 13.751 | CB7: 6.286 | CC7: 1.302 | CD7: 6.271 | CE7: 3.058 | CF7: 4.609 | CG7: 0.128 | CH7: 2.838 | CI7: 4.062 | CJ7: 2.341 | CK7: 0.027 | CL7: 0 | CM7: 3.474 | CN7: 0.116 | CO7: 0.058 | CP7: 0 | CQ7: 5.129 | CR7: 0 | CS7: 0 | CT7: 2.476 | CU7: 0.103 | CV7: 0.32 | CW7: 0 | CX7: 0 | CY7: 0 | CZ7: 1.566 | DA7: 0 | DB7: 0.02 | DC7: 0 | DD7: 1.984 | DE7: 0 | DF7: 0.459 | DG7: 11.468 | DH7: 0 | DI7: 1.332 | DJ7: 0.026 | DK7: 0 | DL7: 0 | DM7: 0.004 | DN7: 0 | DO7: 0 | DP7: 1.015 | DQ7: 0.001 | DR7: 0 | DS7: 0 | DT7: 0 | DU7: 0 | DV7: 0.015 | DW7: 0.476 | DX7: 0 | DY7: 0 | DZ7: 0 | EA7: 0 | EB7: 0.001 | EC7: 0.058 | ED7: 0.008 | EE7: 0 | EF7: 0 | EG7: 0 | EH7: 0 | EI7: 0.743 | EJ7: 0 | EK7: 0 | EL7: 0 | EM7: 0 | EN7: 0 | EO7: 0 | EP7: 0 | EQ7: 0.004 | ER7: 0 | ES7: 0.28 | ET7: 0 | EU7: 0 | EV7: 0 | EW7: 0 | EX7: 0 | EY7: 0 | EZ7: 0 | FA7: 0 | FB7: 0 | FC7: 0 | FD7: 0.004 | FE7: 0 | FF7: 0 | FG7: 0 | FH7: 0 | FI7: 0 | FJ7: 0 | FK7: 0 | FL7: 0 | FM7: 0 | FN7: 0 | FO7: 0 | FP7: 0 | FQ7: 0 | FR7: 0 | FS7: 0 | FT7: 0 | FU7: 0 | FV7: 0 | FW7: 0 | FX7: 0 | FY7: 0 | FZ7: 0 | GA7: 0 | GB7: 0 | GC7: 0 | GD7: 0 | GE7: 0 | GF7: 0 | GG7: 0 | GH7: 0 | GI7: 0 | GJ7: 0 | GK7: 0 | GL7: 0 | GM7: 0 | GN7: 0 | GO7: 0 | GP7: 0 | GQ7: 0 | GR7: 0 | GS7: 0 | GT7: 0 | GU7: 0 | GV7: 0 | GW7: 0 | GX7: 0 | GY7: 0 | GZ7: 0 | HA7: 0 | HB7: 0 | HC7: 0 | HD7: 0 | HE7: 0 | HF7: 0 | HG7: 0 | HH7: 0 | HI7: 0 | HJ7: 0 | HK7: 0 | HL7: 0 | HM7: 5204.039 | HN7: =AVERAGE(C7:HL7) -> 23.871739 | HO7: =MAX(C7:HL7) -> 2164.862 | HP7: =MIN(C7:HL7) -> 0
B8: 1950 | C8: 2541.485 | D8: 78.835 | E8: 415.061 | F8: 510.682 | G8: 102.541 | H8: 61.103 | I8: 500.792 | J8: 154.134 | K8: 131.685 | L8: 124.883 | M8: 202.279 | N8: 41.431 | O8: 112.123 | P8: 61.031 | Q8: 9.601 | R8: 30.508 | S8: 2.184 | T8: 55.738 | U8: 5.141 | V8: 19.659 | W8: 3.511 | X8: 9.831 | Y8: 33.035 | Z8: 45.157 | AA8: 9.488 | AB8: 51.286 | AC8: 3.784 | AD8: 57.854 | AE8: 29.921 | AF8: 76.2 | AG8: 19.417 | AH8: 0.956 | AI8: 38.341 | AJ8: 10.233 | AK8: 3.655 | AL8: 17.132 | AM8: 5.355 | AN8: 0 | AO8: 0.78 | AP8: 3.784 | AQ8: 1.48 | AR8: 18.853 | AS8: 1.649 | AT8: 2.257 | AU8: 18.39 | AV8: 28.656 | AW8: 4.128 | AX8: 20.894 | AY8: 7.498 | AZ8: 3.604 | BA8: 0.385 | BB8: 7.262 | BC8: 21.988 | BD8: 6.545 | BE8: 18.52 | BF8: 9.384 | BG8: 7.931 | BH8: 10.233 | BI8: 1.669 | BJ8: 5.618 | BK8: 5.661 | BL8: 8.953 | BM8: 0.143 | BN8: 0.352 | BO8: 8.432 | BP8: 1.914 | BQ8: 9.726 | BR8: 0.414 | BS8: 2.56 | BT8: 0.993 | BU8: 4.545 | BV8: 8.569 | BW8: 1.319 | BX8: 5.641 | BY8: 0 | BZ8: 6.851 | CA8: 2.352 | CB8: 6.997 | CC8: 0.74 | CD8: 6.992 | CE8: 2.946 | CF8: 1.381 | CG8: 1.219 | CH8: 2.727 | CI8: 4.526 | CJ8: 2.249 | CK8: 0.348 | CL8: 0.286 | CM8: 3.873 | CN8: 1.512 | CO8: 7.419 | CP8: 0.172 | CQ8: 3.18 | CR8: 0.187 | CS8: 0.059 | CT8: 2.756 | CU8: 0.802 | CV8: 0.517 | CW8: 1.627 | CX8: 0.909 | CY8: 6.164 | CZ8: 1.507 | DA8: 0.505 | DB8: 0.622 | DC8: 0.271 | DD8: 2.21 | DE8: 0.638 | DF8: 2.508 | DG8: 0.414 | DH8: 0.551 | DI8: 1.482 | DJ8: 0.711 | DK8: 0.498 | DL8: 0.267 | DM8: 0.088 | DN8: 0.01 | DO8: 0.139 | DP8: 0.297 | DQ8: 0.301 | DR8: 0.362 | DS8: 0.286 | DT8: 2.33 | DU8: 0.268 | DV8: 0.084 | DW8: 1.48 | DX8: 0 | DY8: 0 | DZ8: 0.026 | EA8: 0.055 | EB8: 0.063 | EC8: 0.901 | ED8: 0.191 | EE8: 0.089 | EF8: 0.055 | EG8: 0 | EH8: 0.22 | EI8: 0.74 | EJ8: 0.011 | EK8: 0 | EL8: 0.202 | EM8: 0.213 | EN8: 0.106 | EO8: 0.138 | EP8: 0.26 | EQ8: 0.304 | ER8: 0.245 | ES8: 0.269 | ET8: 0.182 | EU8: 0 | EV8: 0 | EW8: 0 | EX8: 0.004 | EY8: 0.114 | EZ8: 0 | FA8: 0.41 | FB8: 0.026 | FC8: 0 | FD8: 0.073 | FE8: 0.683 | FF8: 0.028 | FG8: 0 | FH8: 0.235 | FI8: 0.048 | FJ8: 0.121 | FK8: 0.03 | FL8: 0.004 | FM8: 0.044 | FN8: 0.158 | FO8: 0.099 | FP8: 0.048 | FQ8: 0.017 | FR8: 0 | FS8: 0.04 | FT8: 0 | FU8: 0.044 | FV8: 0 | FW8: 0.012 | FX8: 0.018 | FY8: 0.011 | FZ8: 0 | GA8: 0.015 | GB8: 0 | GC8: 0.103 | GD8: 0.004 | GE8: 0.009 | GF8: 0 | GG8: 0.047 | GH8: 0 | GI8: 0 | GJ8: 0 | GK8: 0.007 | GL8: 0 | GM8: 0.007 | GN8: 0.006 | GO8: 0.004 | GP8: 0.083 | GQ8: 0.004 | GR8: 0 | GS8: 0 | GT8: 0 | GU8: 0 | GV8: 0 | GW8: 0 | GX8: 0.007 | GY8: 0 | GZ8: 0 | HA8: 0.015 | HB8: 0 | HC8: 0 | HD8: 0 | HE8: 0 | HF8: 0 | HG8: 0 | HH8: 0 | HI8: 0 | HJ8: 0 | HK8: 0 | HL8: 0 | HM8: 5930.25 | HN8: =AVERAGE(C8:HL8) -> 27.202982 | HO8: =MAX(C8:HL8) -> 2541.485 | HP8: =MIN(C8:HL8) -> 0
B9: 1951 | C9: 2618.711 | D9: 102.115 | E9: 449.832 | F9: 576.866 | G9: 123.458 | H9: 64.022 | I9: 545.253 | J9: 162.678 | K9: 142.722 | L9: 149.286 | M9: 228.729 | N9: 48.822 | O9: 122.132 | P9: 65.142 | Q9: 6.914 | R9: 34.889 | S9: 2.924 | T9: 61.122 | U9: 0 | V9: 21.659 | W9: 3.891 | X9: 9.39 | Y9: 33.115 | Z9: 48.953 | AA9: 10.184 | AB9: 54.968 | AC9: 4.908 | AD9: 61.651 | AE9: 34.963 | AF9: 89.45 | AG9: 22.503 | AH9: 1.091 | AI9: 47.38 | AJ9: 10.559 | AK9: 5.22 | AL9: 18.519 | AM9: 6.613 | AN9: 0 | AO9: 0.996 | AP9: 4.131 | AQ9: 1.285 | AR9: 20.426 | AS9: 2.429 | AT9: 1.685 | AU9: 22.185 | AV9: 33.437 | AW9: 4.575 | AX9: 23.264 | AY9: 8.165 | AZ9: 3.553 | BA9: 0.117 | BB9: 8.164 | BC9: 21.921 | BD9: 7.977 | BE9: 19.732 | BF9: 9.982 | BG9: 7.508 | BH9: 12.298 | BI9: 2.918 | BJ9: 5.394 | BK9: 6.126 | BL9: 9.694 | BM9: 0.169 | BN9: 0.388 | BO9: 9.476 | BP9: 2.826 | BQ9: 10.507 | BR9: 0.381 | BS9: 2.926 | BT9: 1.226 | BU9: 4.773 | BV9: 8.17 | BW9: 1.557 | BX9: 6.469 | BY9: 0 | BZ9: 7.426 | CA9: 2.514 | CB9: 7.576 | CC9: 0.704 | CD9: 7.579 | CE9: 2.789 | CF9: 1.176 | CG9: 1.377 | CH9: 2.581 | CI9: 4.905 | CJ9: 2.129 | CK9: 0.359 | CL9: 0.293 | CM9: 4.199 | CN9: 1.457 | CO9: 9.009 | CP9: 0.161 | CQ9: 3.506 | CR9: 0.249 | CS9: 0.04 | CT9: 2.984 | CU9: 0.916 | CV9: 0.462 | CW9: 1.546 | CX9: 1.392 | CY9: 9.722 | CZ9: 1.427 | DA9: 0.664 | DB9: 0.637 | DC9: 0.52 | DD9: 2.395 | DE9: 0.876 | DF9: 2.622 | DG9: 0.3 | DH9: 0.461 | DI9: 1.605 | DJ9: 0.751 | DK9: 0.447 | DL9: 0.282 | DM9: 0.062 | DN9: 0.014 | DO9: 0.183 | DP9: 0.403 | DQ9: 0.348 | DR9: 0.302 | DS9: 0.312 | DT9: 2.569 | DU9: 0.323 | DV9: 0.092 | DW9: 1.747 | DX9: 0 | DY9: 0 | DZ9: 0.029 | EA9: 0.062 | EB9: 0.048 | EC9: 0.93 | ED9: 0.201 | EE9: 0.118 | EF9: 0.066 | EG9: 0 | EH9: 0.282 | EI9: 0.645 | EJ9: 0.011 | EK9: 0 | EL9: 0.139 | EM9: 0.234 | EN9: 0.139 | EO9: 0.115 | EP9: 0.286 | EQ9: 0.245 | ER9: 0.256 | ES9: 0.255 | ET9: 0.153 | EU9: 0 | EV9: 0 | EW9: 0 | EX9: 0.003 | EY9: 0.132 | EZ9: 0 | FA9: 0.646 | FB9: 0.026 | FC9: 0 | FD9: 0.11 | FE9: 1.076 | FF9: 0.024 | FG9: 0 | FH9: 0.259 | FI9: 0.044 | FJ9: 0.132 | FK9: 0.039 | FL9: 0.004 | FM9: 0.058 | FN9: 0.095 | FO9: 0.099 | FP9: 0.048 | FQ9: 0.017 | FR9: 0 | FS9: 0.04 | FT9: 0 | FU9: 0.059 | FV9: 0 | FW9: 0.02 | FX9: 0.026 | FY9: 0.026 | FZ9: 0 | GA9: 0.015 | GB9: 0 | GC9: 0.077 | GD9: 0.011 | GE9: 0.009 | GF9: 0 | GG9: 0.063 | GH9: 0 | GI9: 0 | GJ9: 0 | GK9: 0.004 | GL9: 0 | GM9: 0.011 | GN9: 0.01 | GO9: 0.004 | GP9: 0.13 | GQ9: 0.004 | GR9: 0 | GS9: 0 | GT9: 0 | GU9: 0 | GV9: 0.004 | GW9: 0 | GX9: 0.007 | GY9: 0 | GZ9: 0.004 | HA9: 0.022 | HB9: 0 | HC9: 0 | HD9: 0 | HE9: 0 | HF9: 0 | HG9: 0 | HH9: 0 | HI9: 0 | HJ9: 0 | HK9: 0 | HL9: 0 | HM9: 6381.429 | HN9: =AVERAGE(C9:HL9) -> 29.27261 | HO9: =MAX(C9:HL9) -> 2618.711 | HP9: =MIN(C9:HL9) -> 0
B10: 1952 | C10: 2551.219 | D10: 127.999 | E10: 481.701 | F10: 610.981 | G10: 130.428 | H10: 67.426 | I10: 528.706 | J10: 159.409 | K10: 152.833 | L10: 152.021 | M10: 226.986 | N10: 50.621 | O10: 128.042 | P10: 70.883 | Q10: 4.092 | R10: 37.212 | S10: 3.462 | T10: 62.447 | U10: 0 | V10: 24.934 | W10: 4.135 | X10: 12.721 | Y10: 37.603 | Z10: 52.43 | AA10: 10.474 | AB10: 54.715 | AC10: 6.392 | AD10: 65.919 | AE10: 36.095 | AF10: 83.464 | AG10: 26.631 | AH10: 1.278 | AI10: 50.743 | AJ10: 10.893 | AK10: 6.371 | AL10: 19.811 | AM10: 6.983 | AN10: 0 | AO10: 0.89 | AP10: 3.889 | AQ10: 1.864 | AR10: 21.876 | AS10: 1.96 | AT10: 2.18 | AU10: 27.208 | AV10: 34.521 | AW10: 4.797 | AX10: 22.07 | AY10: 9.428 | AZ10: 4.051 | BA10: 0 | BB10: 8.633 | BC10: 22.899 | BD10: 8.655 | BE10: 21.098 | BF10: 10.604 | BG10: 7.54 | BH10: 11.225 | BI10: 3.659 | BJ10: 5.35 | BK10: 6.559 | BL10: 10.381 | BM10: 0.165 | BN10: 0.194 | BO10: 9.685 | BP10: 3.441 | BQ10: 9.62 | BR10: 0.476 | BS10: 3.563 | BT10: 1.295 | BU10: 5.187 | BV10: 9.32 | BW10: 1.535 | BX10: 6.282 | BY10: 0 | BZ10: 7.952 | CA10: 2.796 | CB10: 8.113 | CC10: 0.895 | CD10: 8.118 | CE10: 2.795 | CF10: 1.286 | CG10: 1.443 | CH10: 2.592 | CI10: 5.253 | CJ10: 2.137 | CK10: 0.593 | CL10: 0.3 | CM10: 4.497 | CN10: 1.175 | CO10: 9.401 | CP10: 0.194 | CQ10: 3.944 | CR10: 0.311 | CS10: 0.059 | CT10: 3.195 | CU10: 1.132 | CV10: 0.513 | CW10: 1.938 | CX10: 1.59 | CY10: 5.613 | CZ10: 1.425 | DA10: 0.697 | DB10: 0.645 | DC10: 0.564 | DD10: 2.564 | DE10: 0.868 | DF10: 3.153 | DG10: 0.322 | DH10: 0.515 | DI10: 1.718 | DJ10: 0.908 | DK10: 0.539 | DL10: 0.315 | DM10: 0.099 | DN10: 0.018 | DO10: 0.282 | DP10: 0.374 | DQ10: 0.359 | DR10: 0.327 | DS10: 0.388 | DT10: 2.89 | DU10: 0.389 | DV10: 0.092 | DW10: 2.084 | DX10: 0 | DY10: 0 | DZ10: 0.029 | EA10: 0.084 | EB10: 0.103 | EC10: 1.073 | ED10: 0.275 | EE10: 0.154 | EF10: 0.077 | EG10: 0 | EH10: 0.473 | EI10: 0.777 | EJ10: 0.011 | EK10: 0 | EL10: 0.176 | EM10: 0.267 | EN10: 0.143 | EO10: 0.129 | EP10: 0.337 | EQ10: 0.308 | ER10: 0.242 | ES10: 0.256 | ET10: 0.171 | EU10: 0 | EV10: 0 | EW10: 0 | EX10: 0.004 | EY10: 0.147 | EZ10: 0 | FA10: 0.373 | FB10: 0.044 | FC10: 0 | FD10: 0.088 | FE10: 0.622 | FF10: 0.027 | FG10: 0 | FH10: 0.291 | FI10: 0.055 | FJ10: 0.158 | FK10: 0.051 | FL10: 0.004 | FM10: 0.061 | FN10: 0.18 | FO10: 0.106 | FP10: 0.048 | FQ10: 0.031 | FR10: 0 | FS10: 0.055 | FT10: 0 | FU10: 0.106 | FV10: 0 | FW10: 0.015 | FX10: 0.026 | FY10: 0.026 | FZ10: 0 | GA10: 0.011 | GB10: 0 | GC10: 0.037 | GD10: 0.007 | GE10: 0.016 | GF10: 0 | GG10: 0.081 | GH10: 0 | GI10: 0.004 | GJ10: 0 | GK10: 0.011 | GL10: 0 | GM10: 0.011 | GN10: 0.007 | GO10: 0.011 | GP10: 0.075 | GQ10: 0.007 | GR10: 0 | GS10: 0 | GT10: 0 | GU10: 0 | GV10: 0.007 | GW10: 0 | GX10: 0.007 | GY10: 0 | GZ10: 0.004 | HA10: 0.033 | HB10: 0 | HC10: 0 | HD10: 0 | HE10: 0 | HF10: 0 | HG10: 0 | HH10: 0 | HI10: 0 | HJ10: 0 | HK10: 0 | HL10: 0 | HM10: 6467.462 | HN10: =AVERAGE(C10:HL10) -> 29.667257 | HO10: =MAX(C10:HL10) -> 2551.219 | HP10: =MIN(C10:HL10) -> 0
B11: 1953 | C11: 2612.971 | D11: 133.783 | E11: 509.613 | F11: 623.492 | G11: 145.902 | H11: 68.705 | I11: 540.211 | J11: 160.608 | K11: 161.689 | L11: 157.253 | M11: 214.548 | N11: 55.995 | O11: 139.193 | P11: 70.996 | Q11: 3.829 | R11: 36.707 | S11: 4.693 | T11: 63.036 | U11: 0.476 | V11: 25.218 | W11: 4.85 | X11: 13.08 | Y11: 38.931 | Z11: 55.479 | AA11: 12.965 | AB11: 55.264 | AC11: 6.472 | AD11: 68.322 | AE11: 35.135 | AF11: 82.374 | AG11: 30.627 | AH11: 1.644 | AI11: 47.855 | AJ11: 10.779 | AK11: 6.499 | AL11: 20.935 | AM11: 7.107 | AN11: 0 | AO11: 1.736 | AP11: 3.999 | AQ11: 1.75 | AR11: 23.145 | AS11: 2.527 | AT11: 2.437 | AU11: 31.766 | AV11: 32.549 | AW11: 4.885 | AX11: 21.715 | AY11: 10.586 | AZ11: 4.033 | BA11: 0 | BB11: 10.761 | BC11: 23.151 | BD11: 7.566 | BE11: 21.866 | BF11: 10.403 | BG11: 7.488 | BH11: 10.333 | BI11: 4.04 | BJ11: 5.929 | BK11: 6.937 | BL11: 10.982 | BM11: 0.249 | BN11: 0.366 | BO11: 9.783 | BP11: 3.482 | BQ11: 9.535 | BR11: 0.512 | BS11: 4.171 | BT11: 1.318 | BU11: 5.513 | BV11: 8.551 | BW11: 1.729 | BX11: 6.191 | BY11: 0 | BZ11: 8.414 | CA11: 2.935 | CB11: 8.583 | CC11: 0.821 | CD11: 8.592 | CE11: 2.78 | CF11: 0.997 | CG11: 1.377 | CH11: 2.574 | CI11: 5.558 | CJ11: 2.122 | CK11: 0.619 | CL11: 0.304 | CM11: 4.758 | CN11: 1.248 | CO11: 8.654 | CP11: 0.213 | CQ11: 4.299 | CR11: 0.275 | CS11: 0.07 | CT11: 3.379 | CU11: 1.304 | CV11: 0.538 | CW11: 2.066 | CX11: 1.513 | CY11: 6.497 | CZ11: 1.417 | DA11: 0.765 | DB11: 0.681 | DC11: 0.615 | DD11: 2.713 | DE11: 1.019 | DF11: 3.505 | DG11: 0.344 | DH11: 0.428 | DI11: 1.817 | DJ11: 0.817 | DK11: 0.528 | DL11: 0.366 | DM11: 0.183 | DN11: 0.015 | DO11: 0.202 | DP11: 0.414 | DQ11: 0.333 | DR11: 0.274 | DS11: 0.432 | DT11: 3.15 | DU11: 0.418 | DV11: 0.106 | DW11: 2.289 | DX11: 0 | DY11: 0 | DZ11: 0.037 | EA11: 0.095 | EB11: 0.121 | EC11: 1.081 | ED11: 0.286 | EE11: 0.13 | EF11: 0.081 | EG11: 0 | EH11: 0.399 | EI11: 0.916 | EJ11: 0.011 | EK11: 0 | EL11: 0.187 | EM11: 0.311 | EN11: 0.209 | EO11: 0.107 | EP11: 0.451 | EQ11: 0.253 | ER11: 0.231 | ES11: 0.254 | ET11: 0.142 | EU11: 0 | EV11: 0 | EW11: 0 | EX11: 0.003 | EY11: 0.158 | EZ11: 0 | FA11: 0.432 | FB11: 0.029 | FC11: 0 | FD11: 0.11 | FE11: 0.719 | FF11: 0.022 | FG11: 0 | FH11: 0.317 | FI11: 0.059 | FJ11: 0.169 | FK11: 0.043 | FL11: 0.004 | FM11: 0.067 | FN11: 0.169 | FO11: 0.121 | FP11: 0.048 | FQ11: 0.029 | FR11: 0 | FS11: 0.084 | FT11: 0 | FU11: 0.092 | FV11: 0 | FW11: 0.017 | FX11: 0.029 | FY11: 0.029 | FZ11: 0 | GA11: 0.011 | GB11: 0 | GC11: 0.018 | GD11: 0.011 | GE11: 0.015 | GF11: 0 | GG11: 0.069 | GH11: 0 | GI11: 0.004 | GJ11: 0 | GK11: 0.007 | GL11: 0 | GM11: 0.011 | GN11: 0.009 | GO11: 0.007 | GP11: 0.087 | GQ11: 0.007 | GR11: 0 | GS11: 0 | GT11: 0 | GU11: 0 | GV11: 0.004 | GW11: 0 | GX11: 0.007 | GY11: 0 | GZ11: 0.004 | HA11: 0.029 | HB11: 0 | HC11: 0 | HD11: 0 | HE11: 0 | HF11: 0 | HG11: 0 | HH11: 0 | HI11: 0 | HJ11: 0 | HK11: 0 | HL11: 0 | HM11: 6650.893 | HN11: =AVERAGE(C11:HL11) -> 30.508683 | HO11: =MAX(C11:HL11) -> 2612.971 | HP11: =MIN(C11:HL11) -> 0
B12: 1954 | C12: 2489.462 | D12: 160.877 | E12: 556.575 | F12: 659.732 | G12: 142.681 | H12: 72.414 | I12: 553.01 | J12: 162.968 | K12: 176.593 | L12: 156.959 | M12: 226.352 | N12: 64.938 | O12: 147.568 | P12: 73.898 | Q12: 1.044 | R12: 36.27 | S12: 5.159 | T12: 67.943 | U12: 1.238 | V12: 29.676 | W12: 5.733 | X12: 14.747 | Y12: 39.724 | Z12: 60.609 | AA12: 13.433 | AB12: 58.393 | AC12: 6.487 | AD12: 72.966 | AE12: 36.75 | AF12: 85.735 | AG12: 33.504 | AH12: 2.05 | AI12: 51.199 | AJ12: 11.664 | AK12: 7.004 | AL12: 22.807 | AM12: 7.218 | AN12: 0 | AO12: 4.787 | AP12: 4.152 | AQ12: 2.67 | AR12: 25.273 | AS12: 3.048 | AT12: 2.572 | AU12: 34.009 | AV12: 34.494 | AW12: 5.082 | AX12: 24.506 | AY12: 11.392 | AZ12: 5.33 | BA12: 1.403 | BB12: 9.621 | BC12: 25.577 | BD12: 9.152 | BE12: 23.349 | BF12: 11.08 | BG12: 8.93 | BH12: 12.593 | BI12: 4.325 | BJ12: 5.79 | BK12: 7.567 | BL12: 11.985 | BM12: 0.3 | BN12: 0.608 | BO12: 9.882 | BP12: 3.771 | BQ12: 9.092 | BR12: 0.578 | BS12: 3.584 | BT12: 1.339 | BU12: 6.234 | BV12: 9.067 | BW12: 1.799 | BX12: 5.949 | BY12: 0 | BZ12: 9.191 | CA12: 2.836 | CB12: 9.367 | CC12: 0.963 | CD12: 9.387 | CE12: 3.318 | CF12: 1.044 | CG12: 1.406 | CH12: 3.07 | CI12: 6.07 | CJ12: 2.532 | CK12: 0.626 | CL12: 0.487 | CM12: 5.198 | CN12: 1.307 | CO12: 8.782 | CP12: 0.253 | CQ12: 4.727 | CR12: 0.348 | CS12: 4.455 | CT12: 3.687 | CU12: 1.462 | CV12: 0.788 | CW12: 1.784 | CX12: 1.7 | CY12: 13.141 | CZ12: 1.697 | DA12: 0.751 | DB12: 0.744 | DC12: 0.791 | DD12: 2.962 | DE12: 1.004 | DF12: 3.736 | DG12: 0.359 | DH12: 0.505 | DI12: 1.983 | DJ12: 0.718 | DK12: 0.539 | DL12: 0.443 | DM12: 0.271 | DN12: 0.016 | DO12: 0.231 | DP12: 0.502 | DQ12: 0.377 | DR12: 0.317 | DS12: 0.407 | DT12: 3.464 | DU12: 0.47 | DV12: 0.106 | DW12: 2.816 | DX12: 0 | DY12: 0 | DZ12: 0.04 | EA12: 0.095 | EB12: 0.183 | EC12: 1.143 | ED12: 0.315 | EE12: 0.137 | EF12: 0.084 | EG12: 0 | EH12: 0.52 | EI12: 0.78 | EJ12: 0.029 | EK12: 0 | EL12: 0.187 | EM12: 0.337 | EN12: 0.22 | EO12: 0.126 | EP12: 0.473 | EQ12: 0.289 | ER12: 0.308 | ES12: 0.303 | ET12: 0.167 | EU12: 0 | EV12: 0 | EW12: 0 | EX12: 0.004 | EY12: 0.216 | EZ12: 0 | FA12: 0.873 | FB12: 0.033 | FC12: 0 | FD12: 0.114 | FE12: 1.455 | FF12: 0.026 | FG12: 0.022 | FH12: 0.349 | FI12: 0.103 | FJ12: 0.158 | FK12: 0.046 | FL12: 0.004 | FM12: 0.066 | FN12: 0.125 | FO12: 0.103 | FP12: 0.048 | FQ12: 0.012 | FR12: 0 | FS12: 0.077 | FT12: 0 | FU12: 0.084 | FV12: 0 | FW12: 0.012 | FX12: 0.029 | FY12: 0.033 | FZ12: 0 | GA12: 0.015 | GB12: 0 | GC12: 0.022 | GD12: 0.007 | GE12: 0.006 | GF12: 0 | GG12: 0.072 | GH12: 0 | GI12: 0.004 | GJ12: 0 | GK12: 0.007 | GL12: 0 | GM12: 0.011 | GN12: 0.006 | GO12: 0.007 | GP12: 0.176 | GQ12: 0.011 | GR12: 0 | GS12: 0 | GT12: 0 | GU12: 0 | GV12: 0.004 | GW12: 0 | GX12: 0.007 | GY12: 0 | GZ12: 0.004 | HA12: 0.033 | HB12: 0 | HC12: 0 | HD12: 0 | HE12: 0 | HF12: 0 | HG12: 0 | HH12: 0 | HI12: 0 | HJ12: 0 | HK12: 0 | HL12: 0 | HM12: 6789.528 | HN12: =AVERAGE(C12:HL12) -> 31.144624 | HO12: =MAX(C12:HL12) -> 2489.462 | HP12: =MIN(C12:HL12) -> 0
B13: 1955 | C13: 2728.512 | D13: 190.521 | E13: 631.101 | F13: 723.498 | G13: 142.036 | H13: 78.788 | I13: 576.952 | J13: 169.473 | K13: 200.239 | L13: 180.529 | M13: 238.982 | N13: 73.266 | O13: 154.202 | P13: 82.936 | Q13: 15.813 | R13: 39.662 | S13: 6.445 | T13: 71.968 | U13: 2.114 | V13: 34.024 | W13: 6.562 | X13: 20.844 | Y13: 40.272 | Z13: 68.734 | AA13: 13.619 | AB13: 60.986 | AC13: 7.197 | AD13: 75.747 | AE13: 39.56 | AF13: 92.017 | AG13: 36.782 | AH13: 2.373 | AI13: 59.751 | AJ13: 10.642 | AK13: 7.43 | AL13: 25.85 | AM13: 7.437 | AN13: 0 | AO13: 7.345 | AP13: 4.607 | AQ13: 3.524 | AR13: 28.66 | AS13: 4.099 | AT13: 2.697 | AU13: 35.705 | AV13: 39.096 | AW13: 5.953 | AX13: 29.07 | AY13: 12.092 | AZ13: 6.616 | BA13: 1.847 | BB13: 11.944 | BC13: 27.065 | BD13: 10.925 | BE13: 24.228 | BF13: 11.597 | BG13: 10.227 | BH13: 13.614 | BI13: 4.815 | BJ13: 6.46 | BK13: 8.58 | BL13: 13.591 | BM13: 0.429 | BN13: 0.418 | BO13: 11.414 | BP13: 4.053 | BQ13: 11.715 | BR13: 1.644 | BS13: 3.555 | BT13: 1.379 | BU13: 6.124 | BV13: 9.393 | BW13: 1.879 | BX13: 6.777 | BY13: 0 | BZ13: 10.423 | CA13: 2.722 | CB13: 10.621 | CC13: 1.198 | CD13: 10.648 | CE13: 3.799 | CF13: 1.403 | CG13: 1.596 | CH13: 3.516 | CI13: 6.883 | CJ13: 2.9 | CK13: 0.915 | CL13: 0.59 | CM13: 5.895 | CN13: 1.621 | CO13: 9.885 | CP13: 0.381 | CQ13: 5.574 | CR13: 0.414 | CS13: 2.484 | CT13: 4.18 | CU13: 1.421 | CV13: 0.931 | CW13: 1.663 | CX13: 1.985 | CY13: 10.87 | CZ13: 1.944 | DA13: 0.852 | DB13: 0.916 | DC13: 0.985 | DD13: 3.359 | DE13: 1.187 | DF13: 3.919 | DG13: 0.3 | DH13: 0.503 | DI13: 2.248 | DJ13: 0.791 | DK13: 0.557 | DL13: 0.451 | DM13: 0.227 | DN13: 0.016 | DO13: 0.234 | DP13: 0.663 | DQ13: 0.436 | DR13: 0.292 | DS13: 0.348 | DT13: 4.085 | DU13: 0.462 | DV13: 0.154 | DW13: 3.388 | DX13: 0.103 | DY13: 0.026 | DZ13: 0.044 | EA13: 0.128 | EB13: 0.19 | EC13: 1.373 | ED13: 0.392 | EE13: 0.135 | EF13: 0.128 | EG13: 0 | EH13: 0.7 | EI13: 0.912 | EJ13: 0.037 | EK13: 0 | EL13: 0.128 | EM13: 0.311 | EN13: 0.264 | EO13: 0.126 | EP13: 0.517 | EQ13: 0.304 | ER13: 0.341 | ES13: 0.347 | ET13: 0.166 | EU13: 0 | EV13: 0 | EW13: 0 | EX13: 0.004 | EY13: 0.267 | EZ13: 0 | FA13: 0.722 | FB13: 0.04 | FC13: 0 | FD13: 0.128 | FE13: 1.204 | FF13: 0.026 | FG13: 0.022 | FH13: 0.411 | FI13: 0.059 | FJ13: 0.172 | FK13: 0.045 | FL13: 0.004 | FM13: 0.075 | FN13: 0.183 | FO13: 0.209 | FP13: 0.066 | FQ13: 0.014 | FR13: 0.044 | FS13: 0.099 | FT13: 0 | FU13: 0.11 | FV13: 0 | FW13: 0.022 | FX13: 0.029 | FY13: 0.037 | FZ13: 0 | GA13: 0.015 | GB13: 0 | GC13: 0.022 | GD13: 0.011 | GE13: 0.008 | GF13: 0 | GG13: 0.072 | GH13: 0 | GI13: 0.011 | GJ13: 0.011 | GK13: 0.011 | GL13: 0 | GM13: 0.011 | GN13: 0.011 | GO13: 0.007 | GP13: 0.146 | GQ13: 0.011 | GR13: 0 | GS13: 0 | GT13: 0 | GU13: 0 | GV13: 0.004 | GW13: 0 | GX13: 0.007 | GY13: 0 | GZ13: 0.004 | HA13: 0.037 | HB13: 0 | HC13: 0 | HD13: 0 | HE13: 0 | HF13: 0 | HG13: 0 | HH13: 0 | HI13: 0 | HJ13: 0 | HK13: 0 | HL13: 0 | HM13: 7443.899 | HN13: =AVERAGE(C13:HL13) -> 34.146326 | HO13: =MAX(C13:HL13) -> 2728.512 | HP13: =MIN(C13:HL13) -> 0
B14: 1956 | C14: 2859.995 | D14: 215.824 | E14: 691.942 | F14: 766.191 | G14: 160.823 | H14: 81.656 | I14: 574.324 | J14: 189.802 | K14: 219.531 | L14: 193.561 | M14: 268.499 | N14: 83.475 | O14: 166.417 | P14: 87.263 | Q14: 22.808 | R14: 42.134 | S14: 7.555 | T14: 75.482 | U14: 1.63 | V14: 36.608 | W14: 7.662 | X14: 21.811 | Y14: 42.333 | Z14: 75.358 | AA14: 14.359 | AB14: 65.079 | AC14: 7.685 | AD14: 81.281 | AE14: 44.297 | AF14: 96.78 | AG14: 40.779 | AH14: 2.618 | AI14: 65.008 | AJ14: 9.942 | AK14: 7.563 | AL14: 28.414 | AM14: 8.812 | AN14: 0 | AO14: 8.963 | AP14: 4.995 | AQ14: 2.908 | AR14: 31.437 | AS14: 6.395 | AT14: 3.012 | AU14: 33.163 | AV14: 43.375 | AW14: 6.286 | AX14: 28.205 | AY14: 12.967 | AZ14: 6.253 | BA14: 1.041 | BB14: 12.599 | BC14: 26.372 | BD14: 12.168 | BE14: 25.997 | BF14: 11.832 | BG14: 11.689 | BH14: 17.061 | BI14: 4.794 | BJ14: 7.163 | BK14: 9.422 | BL14: 14.918 | BM14: 0.33 | BN14: 0.506 | BO14: 11.952 | BP14: 4.096 | BQ14: 10.923 | BR14: 2.003 | BS14: 3.519 | BT14: 1.634 | BU14: 6.311 | BV14: 9.675 | BW14: 2.121 | BX14: 5.842 | BY14: 0 | BZ14: 11.428 | CA14: 2.879 | CB14: 11.656 | CC14: 1.296 | CD14: 11.678 | CE14: 4.348 | CF14: 1.055 | CG14: 1.559 | CH14: 4.019 | CI14: 7.549 | CJ14: 3.318 | CK14: 0.985 | CL14: 0.689 | CM14: 6.464 | CN14: 1.885 | CO14: 10.368 | CP14: 0.45 | CQ14: 6.077 | CR14: 0.502 | CS14: 2.33 | CT14: 4.587 | CU14: 1.656 | CV14: 1.106 | CW14: 1.418 | CX14: 2.22 | CY14: 14.058 | CZ14: 2.233 | DA14: 0.825 | DB14: 0.978 | DC14: 1.26 | DD14: 3.684 | DE14: 1.077 | DF14: 4.022 | DG14: 0.297 | DH14: 0.582 | DI14: 2.467 | DJ14: 0.74 | DK14: 0.66 | DL14: 0.674 | DM14: 0.242 | DN14: 0.021 | DO14: 0.238 | DP14: 0.839 | DQ14: 0.454 | DR14: 0.341 | DS14: 0.484 | DT14: 4.453 | DU14: 0.527 | DV14: 0.183 | DW14: 3.175 | DX14: 0.132 | DY14: 0.059 | DZ14: 0.048 | EA14: 0.128 | EB14: 0.198 | EC14: 1.553 | ED14: 0.377 | EE14: 0.176 | EF14: 0.139 | EG14: 0 | EH14: 1.165 | EI14: 0.949 | EJ14: 0.037 | EK14: 0 | EL14: 0.22 | EM14: 0.341 | EN14: 0.264 | EO14: 0.146 | EP14: 0.55 | EQ14: 0.319 | ER14: 0.297 | ES14: 0.397 | ET14: 0.193 | EU14: 0 | EV14: 0 | EW14: 0 | EX14: 0.004 | EY14: 0.264 | EZ14: 0 | FA14: 0.934 | FB14: 0.04 | FC14: 0 | FD14: 0.128 | FE14: 1.557 | FF14: 0.03 | FG14: 0.026 | FH14: 0.448 | FI14: 0.048 | FJ14: 0.194 | FK14: 0.059 | FL14: 0.004 | FM14: 0.072 | FN14: 0.18 | FO14: 0.143 | FP14: 0.07 | FQ14: 0.017 | FR14: 0.044 | FS14: 0.114 | FT14: 0 | FU14: 0.136 | FV14: 0 | FW14: 0.022 | FX14: 0.029 | FY14: 0.029 | FZ14: 0 | GA14: 0.018 | GB14: 0 | GC14: 0.029 | GD14: 0.011 | GE14: 0.009 | GF14: 0 | GG14: 0.093 | GH14: 0 | GI14: 0.011 | GJ14: 0.011 | GK14: 0.011 | GL14: 0 | GM14: 0.011 | GN14: 0.011 | GO14: 0.007 | GP14: 0.188 | GQ14: 0.011 | GR14: 0 | GS14: 0 | GT14: 0 | GU14: 0 | GV14: 0.004 | GW14: 0 | GX14: 0.007 | GY14: 0 | GZ14: 0.007 | HA14: 0.033 | HB14: 0 | HC14: 0 | HD14: 0 | HE14: 0 | HF14: 0 | HG14: 0 | HH14: 0 | HI14: 0 | HJ14: 0 | HK14: 0 | HL14: 0 | HM14: 7926.016 | HN14: =AVERAGE(C14:HL14) -> 36.357872 | HO14: =MAX(C14:HL14) -> 2859.995 | HP14: =MIN(C14:HL14) -> 0
B15: 1957 | C15: 2835.772 | D15: 255.785 | E15: 757.201 | F15: 777.908 | G15: 188.287 | H15: 91.635 | I15: 570.714 | J15: 182.811 | K15: 240.223 | L15: 215.259 | M15: 277.497 | N15: 87.078 | O15: 178.682 | P15: 89.652 | Q15: 21.8 | R15: 49.278 | S15: 8.214 | T15: 75.479 | U15: 2.099 | V15: 35.974 | W15: 8.424 | X15: 22.412 | Y15: 50.213 | Z15: 82.476 | AA15: 15.97 | AB15: 64.408 | AC15: 8.183 | AD15: 84.904 | AE15: 47.608 | AF15: 96.487 | AG15: 45.93 | AH15: 2.922 | AI15: 69.583 | AJ15: 11.917 | AK15: 3.513 | AL15: 31.146 | AM15: 9.105 | AN15: 0 | AO15: 11.289 | AP15: 5.537 | AQ15: 2.876 | AR15: 34.407 | AS15: 5.97 | AT15: 3.184 | AU15: 38.446 | AV15: 38.843 | AW15: 6.814 | AX15: 29.179 | AY15: 14.389 | AZ15: 6.729 | BA15: 2.198 | BB15: 13.651 | BC15: 24.9 | BD15: 12.241 | BE15: 27.141 | BF15: 11.726 | BG15: 12.697 | BH15: 17.694 | BI15: 5.171 | BJ15: 7.782 | BK15: 10.318 | BL15: 16.334 | BM15: 0.311 | BN15: 0.311 | BO15: 11.358 | BP15: 1.729 | BQ15: 9.718 | BR15: 1.981 | BS15: 3.054 | BT15: 1.689 | BU15: 6.674 | BV15: 10.305 | BW15: 2.363 | BX15: 13.866 | BY15: 0 | BZ15: 12.506 | CA15: 2.564 | CB15: 12.757 | CC15: 1.132 | CD15: 12.785 | CE15: 4.717 | CF15: 0.755 | CG15: 1.574 | CH15: 4.365 | CI15: 8.261 | CJ15: 3.6 | CK15: 1.032 | CL15: 0.762 | CM15: 7.075 | CN15: 2.064 | CO15: 10.837 | CP15: 0.494 | CQ15: 6.255 | CR15: 0.619 | CS15: 2.957 | CT15: 5.022 | CU15: 2.099 | CV15: 1.004 | CW15: 2.319 | CX15: 2.282 | CY15: 9.602 | CZ15: 2.412 | DA15: 1.061 | DB15: 0.985 | DC15: 1.604 | DD15: 4.031 | DE15: 1.293 | DF15: 4.432 | DG15: 0.293 | DH15: 0.596 | DI15: 2.701 | DJ15: 0.916 | DK15: 0.762 | DL15: 0.817 | DM15: 0.322 | DN15: 0.022 | DO15: 0.256 | DP15: 1.506 | DQ15: 0.575 | DR15: 0.347 | DS15: 0.462 | DT15: 4.584 | DU15: 0.597 | DV15: 0.293 | DW15: 3.329 | DX15: 0.161 | DY15: 0.059 | DZ15: 0.055 | EA15: 0.147 | EB15: 0.212 | EC15: 1.769 | ED15: 0.418 | EE15: 0.189 | EF15: 0.176 | EG15: 0 | EH15: 1.066 | EI15: 0.964 | EJ15: 0.033 | EK15: 0 | EL15: 0.22 | EM15: 0.374 | EN15: 0.278 | EO15: 0.149 | EP15: 0.535 | EQ15: 0.315 | ER15: 0.311 | ES15: 0.431 | ET15: 0.197 | EU15: 0 | EV15: 0 | EW15: 0 | EX15: 0.004 | EY15: 0.253 | EZ15: 0 | FA15: 0.638 | FB15: 0.048 | FC15: 0 | FD15: 0.136 | FE15: 1.063 | FF15: 0.031 | FG15: 0.029 | FH15: 0.461 | FI15: 0.084 | FJ15: 0.165 | FK15: 0.063 | FL15: 0.004 | FM15: 0.093 | FN15: 0.388 | FO15: 0.161 | FP15: 0.073 | FQ15: 0.019 | FR15: 0.051 | FS15: 0.095 | FT15: 0 | FU15: 0.139 | FV15: 0 | FW15: 0.022 | FX15: 0.029 | FY15: 0.044 | FZ15: 0 | GA15: 0.022 | GB15: 0 | GC15: 0.018 | GD15: 0.011 | GE15: 0.01 | GF15: 0 | GG15: 0.1 | GH15: 0 | GI15: 0.011 | GJ15: 0.015 | GK15: 0.011 | GL15: 0 | GM15: 0.011 | GN15: 0.011 | GO15: 0.007 | GP15: 0.129 | GQ15: 0.015 | GR15: 0 | GS15: 0 | GT15: 0 | GU15: 0 | GV15: 0.004 | GW15: 0 | GX15: 0.007 | GY15: 0 | GZ15: 0.011 | HA15: 0.04 | HB15: 0 | HC15: 0 | HD15: 0 | HE15: 0 | HF15: 0 | HG15: 0 | HH15: 0 | HI15: 0 | HJ15: 0 | HK15: 0 | HL15: 0 | HM15: 8185.644 | HN15: =AVERAGE(C15:HL15) -> 37.548826 | HO15: =MAX(C15:HL15) -> 2835.772 | HP15: =MIN(C15:HL15) -> 0
B16: 1958 | C16: 2747.108 | D16: 524.617 | E16: 808.224 | F16: 756.379 | G16: 181.421 | H16: 95.816 | I16: 556.316 | J16: 182.155 | K16: 256.387 | L16: 198.326 | M16: 266.154 | N16: 87.598 | O16: 176.735 | P16: 96.253 | Q16: 25.229 | R16: 54.008 | S16: 9.009 | T16: 77.936 | U16: 1.997 | V16: 39.054 | W16: 9.581 | X16: 22.206 | Y16: 55.873 | Z16: 88.047 | AA16: 16.035 | AB16: 66.69 | AC16: 9.57 | AD16: 92.772 | AE16: 44.193 | AF16: 87.685 | AG16: 49.794 | AH16: 3.017 | AI16: 54.455 | AJ16: 13.683 | AK16: 3.832 | AL16: 33.321 | AM16: 10.224 | AN16: 0 | AO16: 15.633 | AP16: 5.214 | AQ16: 5.015 | AR16: 36.735 | AS16: 6.666 | AT16: 3.722 | AU16: 39.244 | AV16: 42.071 | AW16: 7.447 | AX16: 28.087 | AY16: 15.627 | AZ16: 7.56 | BA16: 3.69 | BB16: 13.977 | BC16: 26.791 | BD16: 10.607 | BE16: 29.652 | BF16: 12.451 | BG16: 12.513 | BH16: 16.285 | BI16: 5.537 | BJ16: 7.555 | BK16: 11.026 | BL16: 17.448 | BM16: 0.352 | BN16: 0.169 | BO16: 11.186 | BP16: 2.297 | BQ16: 8.956 | BR16: 2.168 | BS16: 3.267 | BT16: 1.896 | BU16: 7.373 | BV16: 10.18 | BW16: 2.374 | BX16: 17.995 | BY16: 0 | BZ16: 13.35 | CA16: 3.477 | CB16: 13.621 | CC16: 1.322 | CD16: 13.655 | CE16: 4.65 | CF16: 1.29 | CG16: 1.446 | CH16: 4.302 | CI16: 8.82 | CJ16: 3.548 | CK16: 1.065 | CL16: 1.136 | CM16: 7.552 | CN16: 1.98 | CO16: 10.086 | CP16: 0.524 | CQ16: 5.588 | CR16: 0.593 | CS16: 1.883 | CT16: 5.364 | CU16: 2.411 | CV16: 0.916 | CW16: 1.949 | CX16: 2.088 | CY16: 8.411 | CZ16: 2.376 | DA16: 1.186 | DB16: 1.128 | DC16: 1.355 | DD16: 4.304 | DE16: 1.363 | DF16: 3.977 | DG16: 0.319 | DH16: 0.498 | DI16: 2.884 | DJ16: 1.121 | DK16: 0.802 | DL16: 0.765 | DM16: 0.319 | DN16: 0.025 | DO16: 0.278 | DP16: 1.201 | DQ16: 0.586 | DR16: 0.355 | DS16: 0.447 | DT16: 4.095 | DU16: 0.597 | DV16: 0.33 | DW16: 2.926 | DX16: 0.198 | DY16: 0.073 | DZ16: 0.059 | EA16: 0.147 | EB16: 0.242 | EC16: 1.817 | ED16: 0.601 | EE16: 0.216 | EF16: 0.18 | EG16: 0 | EH16: 0.74 | EI16: 1.092 | EJ16: 0.048 | EK16: 0 | EL16: 0.209 | EM16: 0.319 | EN16: 0.293 | EO16: 0.125 | EP16: 0.458 | EQ16: 0.374 | ER16: 0.33 | ES16: 0.424 | ET16: 0.165 | EU16: 0 | EV16: 0 | EW16: 0 | EX16: 0.004 | EY16: 0.275 | EZ16: 0 | FA16: 0.559 | FB16: 0.048 | FC16: 0 | FD16: 0.15 | FE16: 0.931 | FF16: 0.026 | FG16: 0.029 | FH16: 0.412 | FI16: 0.161 | FJ16: 0.176 | FK16: 0.072 | FL16: 0.004 | FM16: 0.104 | FN16: 0.209 | FO16: 0.227 | FP16: 0.084 | FQ16: 0.019 | FR16: 0.051 | FS16: 0.117 | FT16: 0 | FU16: 0.147 | FV16: 0 | FW16: 0.029 | FX16: 0.04 | FY16: 0.048 | FZ16: 0 | GA16: 0.026 | GB16: 0 | GC16: 0.015 | GD16: 0.011 | GE16: 0.01 | GF16: 0 | GG16: 0.115 | GH16: 0 | GI16: 0.011 | GJ16: 0.015 | GK16: 0.011 | GL16: 0 | GM16: 0.015 | GN16: 0.011 | GO16: 0.011 | GP16: 0.113 | GQ16: 0.011 | GR16: 0 | GS16: 0 | GT16: 0 | GU16: 0 | GV16: 0.007 | GW16: 0 | GX16: 0.007 | GY16: 0 | GZ16: 0.007 | HA16: 0.04 | HB16: 0 | HC16: 0 | HD16: 0 | HE16: 0 | HF16: 0 | HG16: 0 | HH16: 0 | HI16: 0 | HJ16: 0 | HK16: 0 | HL16: 0 | HM16: 8417.198 | HN16: =AVERAGE(C16:HL16) -> 38.611 | HO16: =MAX(C16:HL16) -> 2747.108 | HP16: =MIN(C16:HL16) -> 0
B17: 1959 | C17: 2831.923 | D17: 720.152 | E17: 849.739 | F17: 755.795 | G17: 192.92 | H17: 101.447 | I17: 546.606 | J17: 184.481 | K17: 269.533 | L17: 202.353 | M17: 261.89 | N17: 94.085 | O17: 189.66 | P17: 94.473 | Q17: 25.569 | R17: 58.287 | S17: 11.221 | T17: 83.072 | U17: 1.854 | V17: 39.017 | W17: 11.017 | X17: 23.862 | Y17: 52.079 | Z17: 92.595 | AA17: 17.192 | AB17: 67.118 | AC17: 10.991 | AD17: 92.872 | AE17: 48.949 | AF17: 88.31 | AG17: 50.643 | AH17: 3.321 | AI17: 65.149 | AJ17: 12.707 | AK17: 3.183 | AL17: 35.05 | AM17: 9.921 | AN17: 0.011 | AO17: 19.866 | AP17: 5.657 | AQ17: 6.605 | AR17: 38.627 | AS17: 7.314 | AT17: 3.565 | AU17: 41.903 | AV17: 42.388 | AW17: 8.121 | AX17: 27.91 | AY17: 19.622 | AZ17: 7.226 | BA17: 3.8 | BB17: 16.087 | BC17: 26.034 | BD17: 13.556 | BE17: 29.661 | BF17: 12.703 | BG17: 14.344 | BH17: 16.602 | BI17: 5.603 | BJ17: 7.98 | BK17: 11.595 | BL17: 18.349 | BM17: 0.432 | BN17: 0.183 | BO17: 11.808 | BP17: 1.799 | BQ17: 12.312 | BR17: 2.226 | BS17: 3.369 | BT17: 1.84 | BU17: 7.216 | BV17: 10.319 | BW17: 2.703 | BX17: 15.665 | BY17: 0 | BZ17: 14.038 | CA17: 3.092 | CB17: 14.319 | CC17: 1.293 | CD17: 14.367 | CE17: 5.332 | CF17: 1.312 | CG17: 1.588 | CH17: 4.931 | CI17: 9.274 | CJ17: 4.068 | CK17: 1.113 | CL17: 1.345 | CM17: 7.943 | CN17: 2.448 | CO17: 10.42 | CP17: 0.655 | CQ17: 6.233 | CR17: 0.619 | CS17: 2.601 | CT17: 5.64 | CU17: 2.777 | CV17: 0.949 | CW17: 2.055 | CX17: 2.208 | CY17: 10.827 | CZ17: 2.726 | DA17: 1.256 | DB17: 1.238 | DC17: 1.839 | DD17: 4.525 | DE17: 1.323 | DF17: 4.388 | DG17: 0.326 | DH17: 0.546 | DI17: 3.032 | DJ17: 1.3 | DK17: 0.689 | DL17: 0.831 | DM17: 0.337 | DN17: 0.022 | DO17: 0.278 | DP17: 1.443 | DQ17: 0.586 | DR17: 0.388 | DS17: 0.385 | DT17: 4.568 | DU17: 0.604 | DV17: 0.385 | DW17: 2.699 | DX17: 0.213 | DY17: 0.077 | DZ17: 0.066 | EA17: 0.161 | EB17: 0.304 | EC17: 1.794 | ED17: 0.48 | EE17: 0.187 | EF17: 0.26 | EG17: 0 | EH17: 0.59 | EI17: 1.238 | EJ17: 0.048 | EK17: 0 | EL17: 0.224 | EM17: 0.366 | EN17: 0.414 | EO17: 0.103 | EP17: 0.553 | EQ17: 0.374 | ER17: 0.388 | ES17: 0.487 | ET17: 0.158 | EU17: 0.033 | EV17: 0.048 | EW17: 0 | EX17: 0.007 | EY17: 0.253 | EZ17: 0 | FA17: 0.719 | FB17: 0.055 | FC17: 0 | FD17: 0.15 | FE17: 1.199 | FF17: 0.022 | FG17: 0.037 | FH17: 0.46 | FI17: 0.143 | FJ17: 0.198 | FK17: 0.062 | FL17: 0.004 | FM17: 0.11 | FN17: 0.234 | FO17: 0.234 | FP17: 0.088 | FQ17: 0.075 | FR17: 0.029 | FS17: 0.099 | FT17: 0 | FU17: 0.136 | FV17: 0 | FW17: 0.029 | FX17: 0.04 | FY17: 0.037 | FZ17: 0 | GA17: 0.018 | GB17: 0 | GC17: 0.018 | GD17: 0.011 | GE17: 0.039 | GF17: 0 | GG17: 0.099 | GH17: 0 | GI17: 0.011 | GJ17: 0.015 | GK17: 0.015 | GL17: 0.012 | GM17: 0.015 | GN17: 0.015 | GO17: 0.011 | GP17: 0.145 | GQ17: 0.015 | GR17: 0 | GS17: 0.011 | GT17: 0 | GU17: 0 | GV17: 0.011 | GW17: 0 | GX17: 0.007 | GY17: 0 | GZ17: 0.007 | HA17: 0.033 | HB17: 0 | HC17: 0 | HD17: 0 | HE17: 0 | HF17: 0 | HG17: 0 | HH17: 0 | HI17: 0 | HJ17: 0 | HK17: 0 | HL17: 0 | HM17: 8854.692 | HN17: =AVERAGE(C17:HL17) -> 40.617853 | HO17: =MAX(C17:HL17) -> 2831.923 | HP17: =MIN(C17:HL17) -> 0
B18: 1960 | C18: 2897.315 | D18: 798.8 | E18: 884.702 | F18: 813.95 | G18: 232.83 | H18: 111.325 | I18: 584.02 | J18: 192.716 | K18: 280.582 | L18: 223.505 | M18: 296.602 | N18: 109.203 | O18: 199.577 | P18: 97.844 | Q18: 37.359 | R18: 63.052 | S18: 12.54 | T18: 87.444 | U18: 2.674 | V18: 46.852 | W18: 14.667 | X18: 21.385 | Y18: 48.866 | Z18: 96.436 | AA18: 16.799 | AB18: 73.438 | AC18: 11.874 | AD18: 99.053 | AE18: 48.764 | AF18: 90.908 | AG18: 53.394 | AH18: 3.709 | AI18: 57.017 | AJ18: 16.033 | AK18: 4.201 | AL18: 36.528 | AM18: 11.926 | AN18: 0.011 | AO18: 23.788 | AP18: 6.151 | AQ18: 7.484 | AR18: 40.227 | AS18: 8.256 | AT18: 3.403 | AU18: 45.328 | AV18: 49.171 | AW18: 9.392 | AX18: 30.784 | AY18: 22.271 | AZ18: 8.325 | BA18: 7.797 | BB18: 16.39 | BC18: 29.75 | BD18: 15.087 | BE18: 31.633 | BF18: 13.476 | BG18: 15.668 | BH18: 19.499 | BI18: 6.46 | BJ18: 8.214 | BK18: 12.079 | BL18: 19.111 | BM18: 0.692 | BN18: 0.176 | BO18: 13.087 | BP18: 1.392 | BQ18: 11.169 | BR18: 3.219 | BS18: 3.636 | BT18: 2.212 | BU18: 8.165 | BV18: 11.532 | BW18: 2.953 | BX18: 13.687 | BY18: 0 | BZ18: 14.618 | CA18: 2.579 | CB18: 14.909 | CC18: 1.762 | CD18: 14.973 | CE18: 5.826 | CF18: 0.575 | CG18: 1.724 | CH18: 5.387 | CI18: 9.658 | CJ18: 4.444 | CK18: 1.04 | CL18: 1.293 | CM18: 8.273 | CN18: 2.576 | CO18: 11.508 | CP18: 0.743 | CQ18: 5.943 | CR18: 0.549 | CS18: 3.631 | CT18: 5.874 | CU18: 2.715 | CV18: 1.004 | CW18: 2.257 | CX18: 2.424 | CY18: 9.309 | CZ18: 2.98 | DA18: 1.25 | DB18: 1.344 | DC18: 1.468 | DD18: 4.711 | DE18: 1.462 | DF18: 4.315 | DG18: 0.333 | DH18: 0.462 | DI18: 3.158 | DJ18: 1.264 | DK18: 0.828 | DL18: 0.886 | DM18: 0.352 | DN18: 0.132 | DO18: 0.271 | DP18: 2.022 | DQ18: 0.615 | DR18: 0.827 | DS18: 0.491 | DT18: 4.355 | DU18: 0.619 | DV18: 0.414 | DW18: 2.319 | DX18: 0.234 | DY18: 0.081 | DZ18: 0.081 | EA18: 0.18 | EB18: 0.304 | EC18: 1.882 | ED18: 0.531 | EE18: 0.224 | EF18: 0.41 | EG18: 0 | EH18: 0.861 | EI18: 1.212 | EJ18: 0.022 | EK18: 0 | EL18: 0.18 | EM18: 0.432 | EN18: 0.421 | EO18: 0.161 | EP18: 0.66 | EQ18: 0.399 | ER18: 0.341 | ES18: 0.531 | ET18: 0.41 | EU18: 0.037 | EV18: 0.121 | EW18: 0 | EX18: 0.044 | EY18: 0.286 | EZ18: 0 | FA18: 0.619 | FB18: 0.066 | FC18: 0 | FD18: 0.172 | FE18: 1.031 | FF18: 0.029 | FG18: 0.051 | FH18: 0.438 | FI18: 0.165 | FJ18: 0.194 | FK18: 0.055 | FL18: 0.033 | FM18: 0.109 | FN18: 0.714 | FO18: 0.224 | FP18: 0.084 | FQ18: 0.07 | FR18: 0.037 | FS18: 0.059 | FT18: 0 | FU18: 0.158 | FV18: 0 | FW18: 0.037 | FX18: 0.044 | FY18: 0.04 | FZ18: 0 | GA18: 0.018 | GB18: 0 | GC18: 0.022 | GD18: 0.015 | GE18: 0.036 | GF18: 0 | GG18: 0.088 | GH18: 0 | GI18: 0.011 | GJ18: 0.015 | GK18: 0.018 | GL18: 0.015 | GM18: 0.022 | GN18: 0.011 | GO18: 0.011 | GP18: 0.125 | GQ18: 0.015 | GR18: 0 | GS18: 0.011 | GT18: 0 | GU18: 0 | GV18: 0.011 | GW18: 0 | GX18: 0.011 | GY18: 0 | GZ18: 0.011 | HA18: 0.037 | HB18: 0 | HC18: 0 | HD18: 0 | HE18: 0 | HF18: 0 | HG18: 0 | HH18: 0 | HI18: 0 | HJ18: 0 | HK18: 0 | HL18: 0 | HM18: 9387.014 | HN18: =AVERAGE(C18:HL18) -> 43.059697 | HO18: =MAX(C18:HL18) -> 2897.315 | HP18: =MIN(C18:HL18) -> 0
... B81: 2023 | C81: 4911.391 | D81: 11902.503 | E81: 1815.925 | F81: 596.151 | G81: 988.785 | H81: 3062.324 | I81: 305.146 | J81: 549.299 | K81: 136.461 | L81: 593.158 | M81: 272.476 | N81: 313.461 | O81: 289.282 | P81: 401.893 | Q81: 817.88 | R81: 482.623 | S81: 577.417 | T81: 382.972 | U81: 736.205 | V81: 486.47 | W81: 523.412 | X81: 733.224 | Y81: 221.616 | Z81: 255.161 | AA81: 432.077 | AB81: 118.668 | AC81: 261.153 | AD81: 85.624 | AE81: 195.806 | AF81: 83.368 | AG81: 68.239 | AH81: 264.389 | AI81: 99.569 | AJ81: 269.006 | AK81: 288.824 | AL81: 124.768 | AM81: 200.667 | AN81: 229.384 | AO81: 60.764 | AP81: 178.133 | AQ81: 334.726 | AR81: 56.491 | AS81: 176.458 | AT81: 128.54 | AU81: 40.19 | AV81: 36.556 | AW81: 55.196 | AX81: 58.578 | AY81: 36.094 | AZ81: 154.579 | BA81: 99.233 | BB81: 105.239 | BC81: 27.265 | BD81: 31.622 | BE81: 30.739 | BF81: 77.288 | BG81: 42.358 | BH81: 32.737 | BI81: 59.489 | BJ81: 37.228 | BK81: 63.363 | BL81: 43.937 | BM81: 60.976 | BN81: 115.712 | BO81: 38.901 | BP81: 49.253 | BQ81: 34.433 | BR81: 25.503 | BS81: 68.668 | BT81: 113.427 | BU81: 55.864 | BV81: 30.119 | BW81: 33.871 | BX81: 23.097 | BY81: 78.511 | BZ81: 10.019 | CA81: 34.318 | CB81: 12.462 | CC81: 43.173 | CD81: 5.962 | CE81: 17.524 | CF81: 36.527 | CG81: 32.793 | CH81: 20.179 | CI81: 6.513 | CJ81: 11.328 | CK81: 32.02 | CL81: 46.87 | CM81: 10.152 | CN81: 19.475 | CO81: 6.993 | CP81: 21.189 | CQ81: 11.164 | CR81: 20.781 | CS81: 10.035 | CT81: 11.769 | CU81: 30.233 | CV81: 23.359 | CW81: 20.318 | CX81: 21.531 | CY81: 2.023 | CZ81: 7.449 | DA81: 20.001 | DB81: 20.382 | DC81: 7.649 | DD81: 9.055 | DE81: 19.647 | DF81: 7.866 | DG81: 11.77 | DH81: 13.196 | DI81: 7.608 | DJ81: 14.018 | DK81: 18.066 | DL81: 7.174 | DM81: 15.227 | DN81: 5.411 | DO81: 9.941 | DP81: 5.144 | DQ81: 11.042 | DR81: 11.901 | DS81: 8.279 | DT81: 7.749 | DU81: 8.23 | DV81: 11.02 | DW81: 4.616 | DX81: 20.178 | DY81: 24.796 | DZ81: 16.677 | EA81: 8.322 | EB81: 8.139 | EC81: 8.023 | ED81: 5.588 | EE81: 7.674 | EF81: 2.505 | EG81: 6.714 | EH81: 5.068 | EI81: 3.762 | EJ81: 6.141 | EK81: 8.377 | EL81: 4.139 | EM81: 2.647 | EN81: 5.614 | EO81: 5.592 | EP81: 3.545 | EQ81: 4.476 | ER81: 1.822 | ES81: 2.328 | ET81: 4.043 | EU81: 4.413 | EV81: 6.762 | EW81: 4.174 | EX81: 6.187 | EY81: 3.522 | EZ81: 3.889 | FA81: 0.867 | FB81: 2.62 | FC81: 3.497 | FD81: 1.192 | FE81: 0.693 | FF81: 2.598 | FG81: 1.057 | FH81: 1.752 | FI81: 0.771 | FJ81: 1.146 | FK81: 3.079 | FL81: 1.104 | FM81: 1.58 | FN81: 1.232 | FO81: 0.596 | FP81: 0.558 | FQ81: 1.54 | FR81: 0.916 | FS81: 0.798 | FT81: 2.062 | FU81: 0.523 | FV81: 1.713 | FW81: 0.645 | FX81: 0.668 | FY81: 0.493 | FZ81: 0.621 | GA81: 0.711 | GB81: 0.424 | GC81: 0.535 | GD81: 0.511 | GE81: 0.71 | GF81: 0.551 | GG81: 0.281 | GH81: 0.632 | GI81: 0.303 | GJ81: 0.222 | GK81: 0.298 | GL81: 0.157 | GM81: 0.339 | GN81: 0.233 | GO81: 0.237 | GP81: 0.115 | GQ81: 0.257 | GR81: 0.371 | GS81: 0.449 | GT81: 0.185 | GU81: 0.226 | GV81: 0.163 | GW81: 0.057 | GX81: 0.199 | GY81: 0.149 | GZ81: 0.166 | HA81: 0.056 | HB81: 0.153 | HC81: 0.145 | HD81: 0.073 | HE81: 0.069 | HF81: 0.022 | HG81: 0 | HH81: 0.031 | HI81: 0.011 | HJ81: 0.012 | HK81: 0.008 | HL81: 0 | HM81: 37791.565 | HN81: =AVERAGE(C81:HL81) -> 173.3558 | HO81: =MAX(C81:HL81) -> 11902.503 | HP81: =MIN(C81:HL81) -> 0
B82: 2024 | C82: =FORECAST($B82,C$7:C81,$B$7:$B81) -> 6296.579 | D82: =FORECAST($B82,D$7:D81,$B$7:$B81) -> 9511.8038 | E82: =FORECAST($B82,E$7:E81,$B$7:$B81) -> 2065.1063 | F82: =FORECAST($B82,F$7:F81,$B$7:$B81) -> 879.52299 | G82: =FORECAST($B82,G$7:G81,$B$7:$B81) -> 1494.9838 | H82: =FORECAST($B82,H$7:H81,$B$7:$B81) -> 2144.8951 | I82: =FORECAST($B82,I$7:I81,$B$7:$B81) -> 457.47313 | J82: =FORECAST($B82,J$7:J81,$B$7:$B81) -> 657.21041 | ... HL82: =FORECAST($B82,HL$7:HL81,$B$7:$B81) -> 0.0037917117 | HM82: =SUM(C82:HL82) -> 38246.698 | HN82: =AVERAGE(C82:HL82) -> 175.44357 | HO82: =MAX(C82:HL82) -> 9511.8038 | HP82: =MIN(C82:HL82) -> 0.0037917117
B83: 2025 | C83: =FORECAST($B83,C$7:C82,$B$7:$B82) -> 6341.3762 | D83: =FORECAST($B83,D$7:D82,$B$7:$B82) -> 9667.2368 | E83: =FORECAST($B83,E$7:E82,$B$7:$B82) -> 2078.9684 | F83: =FORECAST($B83,F$7:F82,$B$7:$B82) -> 879.3931 | G83: =FORECAST($B83,G$7:G82,$B$7:$B82) -> 1511.5716 | H83: =FORECAST($B83,H$7:H82,$B$7:$B82) -> 2179.9402 | I83: =FORECAST($B83,I$7:I82,$B$7:$B82) -> 455.13491 | J83: =FORECAST($B83,J$7:J82,$B$7:$B82) -> 663.64604 | ... HL83: =FORECAST($B83,HL$7:HL82,$B$7:$B82) -> 0.0038364059 | HM83: =SUM(C83:HL83) -> 38694.673 | HN83: =AVERAGE(C83:HL83) -> 177.4985 | HO83: =MAX(C83:HL83) -> 9667.2368 | HP83: =MIN(C83:HL83) -> 0.0037788241
B84: 2026 | C84: =FORECAST($B84,C$7:C83,$B$7:$B83) -> 6386.1735 | D84: =FORECAST($B84,D$7:D83,$B$7:$B83) -> 9822.6698 | E84: =FORECAST($B84,E$7:E83,$B$7:$B83) -> 2092.8305 | F84: =FORECAST($B84,F$7:F83,$B$7:$B83) -> 879.2632 | G84: =FORECAST($B84,G$7:G83,$B$7:$B83) -> 1528.1594 | H84: =FORECAST($B84,H$7:H83,$B$7:$B83) -> 2214.9853 | I84: =FORECAST($B84,I$7:I83,$B$7:$B83) -> 452.79669 | J84: =FORECAST($B84,J$7:J83,$B$7:$B83) -> 670.08166 | ... HL84: =FORECAST($B84,HL$7:HL83,$B$7:$B83) -> 0.0038811 | HM84: =SUM(C84:HL84) -> 39142.647 | HN84: =AVERAGE(C84:HL84) -> 179.55343 | HO84: =MAX(C84:HL84) -> 9822.6698 | HP84: =MIN(C84:HL84) -> 0.0034199905
B85: 2027 | C85: =FORECAST($B85,C$7:C84,$B$7:$B84) -> 6430.9707 | D85: =FORECAST($B85,D$7:D84,$B$7:$B84) -> 9978.1028 | E85: =FORECAST($B85,E$7:E84,$B$7:$B84) -> 2106.6926 | F85: =FORECAST($B85,F$7:F84,$B$7:$B84) -> 879.13331 | G85: =FORECAST($B85,G$7:G84,$B$7:$B84) -> 1544.7472 | H85: =FORECAST($B85,H$7:H84,$B$7:$B84) -> 2250.0304 | I85: =FORECAST($B85,I$7:I84,$B$7:$B84) -> 450.45847 | J85: =FORECAST($B85,J$7:J84,$B$7:$B84) -> 676.51728 | ... HL85: =FORECAST($B85,HL$7:HL84,$B$7:$B84) -> 0.0039257942 | HM85: =SUM(C85:HL85) -> 39590.622 | HN85: =AVERAGE(C85:HL85) -> 181.60836 | HO85: =MAX(C85:HL85) -> 9978.1028 | HP85: =MIN(C85:HL85) -> 0.0030611569
B86: 2028 | C86: =FORECAST($B86,C$7:C85,$B$7:$B85) -> 6475.768 | D86: =FORECAST($B86,D$7:D85,$B$7:$B85) -> 10133.536 | E86: =FORECAST($B86,E$7:E85,$B$7:$B85) -> 2120.5547 | F86: =FORECAST($B86,F$7:F85,$B$7:$B85) -> 879.00341 | G86: =FORECAST($B86,G$7:G85,$B$7:$B85) -> 1561.335 | H86: =FORECAST($B86,H$7:H85,$B$7:$B85) -> 2285.0755 | I86: =FORECAST($B86,I$7:I85,$B$7:$B85) -> 448.12025 | J86: =FORECAST($B86,J$7:J85,$B$7:$B85) -> 682.9529 | ... HL86: =FORECAST($B86,HL$7:HL85,$B$7:$B85) -> 0.0039704884 | HM86: =SUM(C86:HL86) -> 40038.596 | HN86: =AVERAGE(C86:HL86) -> 183.66328 | HO86: =MAX(C86:HL86) -> 10133.536 | HP86: =MIN(C86:HL86) -> 0.0027023234
B87: 2029 | C87: =FORECAST($B87,C$7:C86,$B$7:$B86) -> 6520.5653 | D87: =FORECAST($B87,D$7:D86,$B$7:$B86) -> 10288.969 | E87: =FORECAST($B87,E$7:E86,$B$7:$B86) -> 2134.4167 | F87: =FORECAST($B87,F$7:F86,$B$7:$B86) -> 878.87352 | G87: =FORECAST($B87,G$7:G86,$B$7:$B86) -> 1577.9229 | H87: =FORECAST($B87,H$7:H86,$B$7:$B86) -> 2320.1206 | I87: =FORECAST($B87,I$7:I86,$B$7:$B86) -> 445.78203 | J87: =FORECAST($B87,J$7:J86,$B$7:$B86) -> 689.38852 | ... HL87: =FORECAST($B87,HL$7:HL86,$B$7:$B86) -> 0.0040151826 | HM87: =SUM(C87:HL87) -> 40486.571 | HN87: =AVERAGE(C87:HL87) -> 185.71821 | HO87: =MAX(C87:HL87) -> 10288.969 | HP87: =MIN(C87:HL87) -> 0.0023434898
B88: 2030 | C88: =FORECAST($B88,C$7:C87,$B$7:$B87) -> 6565.3625 | D88: =FORECAST($B88,D$7:D87,$B$7:$B87) -> 10444.402 | E88: =FORECAST($B88,E$7:E87,$B$7:$B87) -> 2148.2788 | F88: =FORECAST($B88,F$7:F87,$B$7:$B87) -> 878.74362 | G88: =FORECAST($B88,G$7:G87,$B$7:$B87) -> 1594.5107 | H88: =FORECAST($B88,H$7:H87,$B$7:$B87) -> 2355.1657 | I88: =FORECAST($B88,I$7:I87,$B$7:$B87) -> 443.44381 | J88: =FORECAST($B88,J$7:J87,$B$7:$B87) -> 695.82414 | ... HL88: =FORECAST($B88,HL$7:HL87,$B$7:$B87) -> 0.0040598767 | HM88: =SUM(C88:HL88) -> 40934.545 | HN88: =AVERAGE(C88:HL88) -> 187.77314 | HO88: =MAX(C88:HL88) -> 10444.402 | HP88: =MIN(C88:HL88) -> 0.0019846562
B89: 2031 | C89: =FORECAST($B89,C$7:C88,$B$7:$B88) -> 6610.1598 | D89: =FORECAST($B89,D$7:D88,$B$7:$B88) -> 10599.835 | E89: =FORECAST($B89,E$7:E88,$B$7:$B88) -> 2162.1409 | F89: =FORECAST($B89,F$7:F88,$B$7:$B88) -> 878.61373 | G89: =FORECAST($B89,G$7:G88,$B$7:$B88) -> 1611.0985 | H89: =FORECAST($B89,H$7:H88,$B$7:$B88) -> 2390.2108 | I89: =FORECAST($B89,I$7:I88,$B$7:$B88) -> 441.1056 | J89: =FORECAST($B89,J$7:J88,$B$7:$B88) -> 702.25977 | ... HL89: =FORECAST($B89,HL$7:HL88,$B$7:$B88) -> 0.0041045709 | HM89: =SUM(C89:HL89) -> 41382.519 | HN89: =AVERAGE(C89:HL89) -> 189.82807 | HO89: =MAX(C89:HL89) -> 10599.835 | HP89: =MIN(C89:HL89) -> 0.0016258227
B90: 2032 | C90: =FORECAST($B90,C$7:C89,$B$7:$B89) -> 6654.957 | D90: =FORECAST($B90,D$7:D89,$B$7:$B89) -> 10755.268 | E90: =FORECAST($B90,E$7:E89,$B$7:$B89) -> 2176.003 | F90: =FORECAST($B90,F$7:F89,$B$7:$B89) -> 878.48383 | G90: =FORECAST($B90,G$7:G89,$B$7:$B89) -> 1627.6863 | H90: =FORECAST($B90,H$7:H89,$B$7:$B89) -> 2425.2559 | I90: =FORECAST($B90,I$7:I89,$B$7:$B89) -> 438.76738 | J90: =FORECAST($B90,J$7:J89,$B$7:$B89) -> 708.69539 | ... HL90: =FORECAST($B90,HL$7:HL89,$B$7:$B89) -> 0.0041492651 | HM90: =SUM(C90:HL90) -> 41830.494 | HN90: =AVERAGE(C90:HL90) -> 191.883 | HO90: =MAX(C90:HL90) -> 10755.268 | HP90: =MIN(C90:HL90) -> 0.0012669891
B91: 2033 | C91: =FORECAST($B91,C$7:C90,$B$7:$B90) -> 6699.7543 | D91: =FORECAST($B91,D$7:D90,$B$7:$B90) -> 10910.701 | E91: =FORECAST($B91,E$7:E90,$B$7:$B90) -> 2189.865 | F91: =FORECAST($B91,F$7:F90,$B$7:$B90) -> 878.35394 | G91: =FORECAST($B91,G$7:G90,$B$7:$B90) -> 1644.2741 | H91: =FORECAST($B91,H$7:H90,$B$7:$B90) -> 2460.301 | I91: =FORECAST($B91,I$7:I90,$B$7:$B90) -> 436.42916 | J91: =FORECAST($B91,J$7:J90,$B$7:$B90) -> 715.13101 | ... HL91: =FORECAST($B91,HL$7:HL90,$B$7:$B90) -> 0.0041939592 | HM91: =SUM(C91:HL91) -> 42278.468 | HN91: =AVERAGE(C91:HL91) -> 193.93793 | HO91: =MAX(C91:HL91) -> 10910.701 | HP91: =MIN(C91:HL91) -> 0.00090815552
B92: 2034 | C92: =FORECAST($B92,C$7:C91,$B$7:$B91) -> 6744.5515 | D92: =FORECAST($B92,D$7:D91,$B$7:$B91) -> 11066.134 | E92: =FORECAST($B92,E$7:E91,$B$7:$B91) -> 2203.7271 | F92: =FORECAST($B92,F$7:F91,$B$7:$B91) -> 878.22404 | G92: =FORECAST($B92,G$7:G91,$B$7:$B91) -> 1660.862 | H92: =FORECAST($B92,H$7:H91,$B$7:$B91) -> 2495.3461 | I92: =FORECAST($B92,I$7:I91,$B$7:$B91) -> 434.09094 | J92: =FORECAST($B92,J$7:J91,$B$7:$B91) -> 721.56663 | ... HL92: =FORECAST($B92,HL$7:HL91,$B$7:$B91) -> 0.0042386534 | HM92: =SUM(C92:HL92) -> 42726.443 | HN92: =AVERAGE(C92:HL92) -> 195.99286 | HO92: =MAX(C92:HL92) -> 11066.134 | HP92: =MIN(C92:HL92) -> 0.00054932195
B93: 2035 | C93: =FORECAST($B93,C$7:C92,$B$7:$B92) -> 6789.3488 | D93: =FORECAST($B93,D$7:D92,$B$7:$B92) -> 11221.567 | E93: =FORECAST($B93,E$7:E92,$B$7:$B92) -> 2217.5892 | F93: =FORECAST($B93,F$7:F92,$B$7:$B92) -> 878.09415 | G93: =FORECAST($B93,G$7:G92,$B$7:$B92) -> 1677.4498 | H93: =FORECAST($B93,H$7:H92,$B$7:$B92) -> 2530.3912 | I93: =FORECAST($B93,I$7:I92,$B$7:$B92) -> 431.75272 | J93: =FORECAST($B93,J$7:J92,$B$7:$B92) -> 728.00225 | ... HL93: =FORECAST($B93,HL$7:HL92,$B$7:$B92) -> 0.0042833476 | HM93: =SUM(C93:HL93) -> 43174.417 | HN93: =AVERAGE(C93:HL93) -> 198.04779 | HO93: =MAX(C93:HL93) -> 11221.567 | HP93: =MIN(C93:HL93) -> 0.00019048838
... B131: 2073 | C131: =FORECAST($B131,C$7:C130,$B$7:$B130) -> 8491.6445 | D131: =FORECAST($B131,D$7:D130,$B$7:$B130) -> 17128.02 | E131: =FORECAST($B131,E$7:E130,$B$7:$B130) -> 2744.3481 | F131: =FORECAST($B131,F$7:F130,$B$7:$B130) -> 873.15814 | G131: =FORECAST($B131,G$7:G130,$B$7:$B130) -> 2307.7869 | H131: =FORECAST($B131,H$7:H130,$B$7:$B130) -> 3862.1052 | I131: =FORECAST($B131,I$7:I130,$B$7:$B130) -> 342.90042 | J131: =FORECAST($B131,J$7:J130,$B$7:$B130) -> 972.55588 | ... HL131: =FORECAST($B131,HL$7:HL130,$B$7:$B130) -> 0.0059817259 | HM131: =SUM(C131:HL131) -> 60197.448 | HN131: =AVERAGE(C131:HL131) -> 276.13508 | HO131: =MAX(C131:HL131) -> 17128.02 | HP131: =MIN(C131:HL131) -> -1.7113179

Sheet Linear Param 0 & 2
B3: Continent(Gross Continental Product) wise CO2 emission data including international Aviation and Shipping
B5: Year | C5: Parameter 2,0 | O5: Grand Total | P5: Average | Q5: Maximum | R5: Minimum
C6: Asia (GCP) | D6: Europe (GCP) | E6: North America (GCP) | F6: Middle East (GCP) | G6: Africa (GCP) | H6: South America (GCP) | I6: International shipping | J6: Oceania (GCP) | K6: International aviation | L6: Central America (GCP) | M6: Kuwaiti Oil Fires (GCP) | N6: Ryukyu Islands (GCP)
B7: 1949 | C7: 340.849 | D7: 2266.13 | E7: 2338.843 | F7: 41.809 | G7: 77.324 | H7: 71.233 | I7: 0 | J7: 53.673 | K7: 0 | L7: 14.175 | M7: 0 | N7: 0 | O7: 5204.036 | P7: =AVERAGE(C7:N7) -> 433.66967 | Q7: =MAX(C7:N7) -> 2338.843 | R7: =MIN(C7:N7) -> 0
B8: 1950 | C8: 368.852 | D8: 2383.328 | E8: 2726.24 | F8: 31.822 | G8: 94.868 | H8: 113.414 | I8: 124.883 | J8: 64.659 | K8: 3.511 | L8: 18.668 | M8: 0 | N8: 0 | O8: 5930.245 | P8: =AVERAGE(C8:N8) -> 494.18708 | Q8: =MAX(C8:N8) -> 2726.24 | R8: =MIN(C8:N8) -> 0
B9: 1951 | C9: 428.897 | D9: 2630.209 | E9: 2816.4 | F9: 26.167 | G9: 101.125 | H9: 131.277 | I9: 149.286 | J9: 69.717 | K9: 3.891 | L9: 24.46 | M9: 0 | N9: 0 | O9: 6381.429 | P9: =AVERAGE(C9:N9) -> 531.78575 | Q9: =MAX(C9:N9) -> 2816.4 | R9: =MIN(C9:N9) -> 0
B10: 1952 | C10: 481.189 | D10: 2713.979 | E10: 2747.98 | F10: 23.568 | G10: 110.325 | H10: 141.465 | I10: 152.021 | J10: 72.415 | K10: 4.135 | L10: 20.384 | M10: 0 | N10: 0 | O10: 6467.461 | P10: =AVERAGE(C10:N10) -> 538.95508 | Q10: =MAX(C10:N10) -> 2747.98 | R10: =MIN(C10:N10) -> 0
B11: 1953 | C11: 513.187 | D11: 2791.516 | E11: 2810.436 | F11: 27.242 | G11: 112.007 | H11: 140.632 | I11: 157.253 | J11: 72.173 | K11: 4.85 | L11: 21.589 | M11: 0 | N11: 0 | O11: 6650.885 | P11: =AVERAGE(C11:N11) -> 554.24042 | Q11: =MAX(C11:N11) -> 2810.436 | R11: =MIN(C11:N11) -> 0
B12: 1954 | C12: 559.485 | D12: 2970.04 | E12: 2688.836 | F12: 32.736 | G12: 117.536 | H12: 151.041 | I12: 156.959 | J12: 77.71 | K12: 5.733 | L12: 29.452 | M12: 0 | N12: 0 | O12: 6789.528 | P12: =AVERAGE(C12:N12) -> 565.794 | Q12: =MAX(C12:N12) -> 2970.04 | R12: =MIN(C12:N12) -> 0
B13: 1955 | C13: 624.754 | D13: 3233.7 | E13: 2937.893 | F13: 50.259 | G13: 129.402 | H13: 170.066 | I13: 180.529 | J13: 82.317 | K13: 6.562 | L13: 28.414 | M13: 0 | N13: 0 | O13: 7443.896 | P13: =AVERAGE(C13:N13) -> 620.32467 | Q13: =MAX(C13:N13) -> 3233.7 | R13: =MIN(C13:N13) -> 0
B14: 1956 | C14: 690.27 | D14: 3445.256 | E14: 3092.107 | F14: 59.256 | G14: 135.106 | H14: 184.168 | I14: 193.561 | J14: 86.601 | K14: 7.662 | L14: 32.025 | M14: 0 | N14: 0 | O14: 7926.012 | P14: =AVERAGE(C14:N14) -> 660.501 | Q14: =MAX(C14:N14) -> 3445.256 | R14: =MIN(C14:N14) -> 0
B15: 1957 | C15: 782.051 | D15: 3593.218 | E15: 3068.063 | F15: 61.77 | G15: 141.593 | H15: 192.903 | I15: 215.259 | J15: 87.114 | K15: 8.424 | L15: 35.249 | M15: 0 | N15: 0 | O15: 8185.644 | P15: =AVERAGE(C15:N15) -> 682.137 | Q15: =MAX(C15:N15) -> 3593.218 | R15: =MIN(C15:N15) -> 0
B16: 1958 | C16: 1071.082 | D16: 3631.7 | E16: 2983.538 | F16: 67.166 | G16: 148.671 | H16: 178.736 | I16: 198.326 | J16: 89.128 | K16: 9.581 | L16: 39.261 | M16: 0 | N16: 0 | O16: 8417.189 | P16: =AVERAGE(C16:N16) -> 701.43242 | Q16: =MAX(C16:N16) -> 3631.7 | R16: =MIN(C16:N16) -> 0
